2021-06-21 16:43:23,820 ERROR: Exception on /delete_post/11 [GET] [in /Users/janinavolkmer/Python/Flask/The_Good_Quote/venv/lib/python3.9/site-packages/flask/app.py:1454]
Traceback (most recent call last):
  File "/Users/janinavolkmer/Python/Flask/The_Good_Quote/venv/lib/python3.9/site-packages/flask/app.py", line 2070, in wsgi_app
    response = self.full_dispatch_request()
  File "/Users/janinavolkmer/Python/Flask/The_Good_Quote/venv/lib/python3.9/site-packages/flask/app.py", line 1515, in full_dispatch_request
    rv = self.handle_user_exception(e)
  File "/Users/janinavolkmer/Python/Flask/The_Good_Quote/venv/lib/python3.9/site-packages/flask/app.py", line 1513, in full_dispatch_request
    rv = self.dispatch_request()
  File "/Users/janinavolkmer/Python/Flask/The_Good_Quote/venv/lib/python3.9/site-packages/flask/app.py", line 1499, in dispatch_request
    return self.ensure_sync(self.view_functions[rule.endpoint])(**req.view_args)
  File "/Users/janinavolkmer/Python/Flask/The_Good_Quote/venv/lib/python3.9/site-packages/flask_login/utils.py", line 272, in decorated_view
    return func(*args, **kwargs)
  File "/Users/janinavolkmer/Python/Flask/The_Good_Quote/app/routes.py", line 43, in delete_post
    if user.username == current_user:
AttributeError: 'function' object has no attribute 'username'
2021-06-21 16:45:00,272 INFO: TheGoodQuote startup [in /Users/janinavolkmer/Python/Flask/The_Good_Quote/app/__init__.py:49]
2021-06-21 16:47:16,092 INFO: TheGoodQuote startup [in /Users/janinavolkmer/Python/Flask/The_Good_Quote/app/__init__.py:49]
2021-06-21 16:47:23,534 ERROR: Exception on /delete_post/11 [GET] [in /Users/janinavolkmer/Python/Flask/The_Good_Quote/venv/lib/python3.9/site-packages/flask/app.py:1454]
Traceback (most recent call last):
  File "/Users/janinavolkmer/Python/Flask/The_Good_Quote/venv/lib/python3.9/site-packages/sqlalchemy/orm/session.py", line 2592, in delete
    state = attributes.instance_state(instance)
AttributeError: 'function' object has no attribute '_sa_instance_state'

The above exception was the direct cause of the following exception:

Traceback (most recent call last):
  File "/Users/janinavolkmer/Python/Flask/The_Good_Quote/venv/lib/python3.9/site-packages/flask/app.py", line 2070, in wsgi_app
    response = self.full_dispatch_request()
  File "/Users/janinavolkmer/Python/Flask/The_Good_Quote/venv/lib/python3.9/site-packages/flask/app.py", line 1515, in full_dispatch_request
    rv = self.handle_user_exception(e)
  File "/Users/janinavolkmer/Python/Flask/The_Good_Quote/venv/lib/python3.9/site-packages/flask/app.py", line 1513, in full_dispatch_request
    rv = self.dispatch_request()
  File "/Users/janinavolkmer/Python/Flask/The_Good_Quote/venv/lib/python3.9/site-packages/flask/app.py", line 1499, in dispatch_request
    return self.ensure_sync(self.view_functions[rule.endpoint])(**req.view_args)
  File "/Users/janinavolkmer/Python/Flask/The_Good_Quote/venv/lib/python3.9/site-packages/flask_login/utils.py", line 272, in decorated_view
    return func(*args, **kwargs)
  File "/Users/janinavolkmer/Python/Flask/The_Good_Quote/app/routes.py", line 44, in delete_post
    db.session.delete(post)
  File "<string>", line 2, in delete
  File "/Users/janinavolkmer/Python/Flask/The_Good_Quote/venv/lib/python3.9/site-packages/sqlalchemy/orm/session.py", line 2594, in delete
    util.raise_(
  File "/Users/janinavolkmer/Python/Flask/The_Good_Quote/venv/lib/python3.9/site-packages/sqlalchemy/util/compat.py", line 207, in raise_
    raise exception
sqlalchemy.orm.exc.UnmappedInstanceError: Class 'builtins.method' is not mapped
2021-06-21 16:48:32,352 INFO: TheGoodQuote startup [in /Users/janinavolkmer/Python/Flask/The_Good_Quote/app/__init__.py:49]
2021-06-21 16:48:38,529 ERROR: Exception on /delete_post/11 [GET] [in /Users/janinavolkmer/Python/Flask/The_Good_Quote/venv/lib/python3.9/site-packages/flask/app.py:1454]
Traceback (most recent call last):
  File "/Users/janinavolkmer/Python/Flask/The_Good_Quote/venv/lib/python3.9/site-packages/sqlalchemy/orm/session.py", line 2592, in delete
    state = attributes.instance_state(instance)
AttributeError: 'function' object has no attribute '_sa_instance_state'

The above exception was the direct cause of the following exception:

Traceback (most recent call last):
  File "/Users/janinavolkmer/Python/Flask/The_Good_Quote/venv/lib/python3.9/site-packages/flask/app.py", line 2070, in wsgi_app
    response = self.full_dispatch_request()
  File "/Users/janinavolkmer/Python/Flask/The_Good_Quote/venv/lib/python3.9/site-packages/flask/app.py", line 1515, in full_dispatch_request
    rv = self.handle_user_exception(e)
  File "/Users/janinavolkmer/Python/Flask/The_Good_Quote/venv/lib/python3.9/site-packages/flask/app.py", line 1513, in full_dispatch_request
    rv = self.dispatch_request()
  File "/Users/janinavolkmer/Python/Flask/The_Good_Quote/venv/lib/python3.9/site-packages/flask/app.py", line 1499, in dispatch_request
    return self.ensure_sync(self.view_functions[rule.endpoint])(**req.view_args)
  File "/Users/janinavolkmer/Python/Flask/The_Good_Quote/venv/lib/python3.9/site-packages/flask_login/utils.py", line 272, in decorated_view
    return func(*args, **kwargs)
  File "/Users/janinavolkmer/Python/Flask/The_Good_Quote/app/routes.py", line 43, in delete_post
    db.session.delete(post)
  File "<string>", line 2, in delete
  File "/Users/janinavolkmer/Python/Flask/The_Good_Quote/venv/lib/python3.9/site-packages/sqlalchemy/orm/session.py", line 2594, in delete
    util.raise_(
  File "/Users/janinavolkmer/Python/Flask/The_Good_Quote/venv/lib/python3.9/site-packages/sqlalchemy/util/compat.py", line 207, in raise_
    raise exception
sqlalchemy.orm.exc.UnmappedInstanceError: Class 'builtins.method' is not mapped
